/datadrive/Crontab/light_house_bot.py:1399: TelegramDeprecationWarning: The argument `clean` of `start_polling` is deprecated. Please use `drop_pending_updates` instead.
  updater.start_polling(timeout=3, clean=True) #drop_pending_updates
start Smartmind_Lighthouse_Bot chat bot
Killed
/datadrive/Crontab/light_house_bot.py:1399: TelegramDeprecationWarning: The argument `clean` of `start_polling` is deprecated. Please use `drop_pending_updates` instead.
  updater.start_polling(timeout=3, clean=True) #drop_pending_updates
[INFO] 2021-05-25 12:54:36,532 > 사용자 id :1459643056  닉 : ㅇ 
[INFO] 2021-05-25 12:56:17,147 > 사용자 id :1861198809  닉 : KIM 
No error handlers are registered, logging exception.
Traceback (most recent call last):
  File "/anaconda/envs/py37_default/lib/python3.7/site-packages/pandas/core/indexes/base.py", line 2646, in get_loc
    return self._engine.get_loc(key)
  File "pandas/_libs/index.pyx", line 111, in pandas._libs.index.IndexEngine.get_loc
  File "pandas/_libs/index.pyx", line 138, in pandas._libs.index.IndexEngine.get_loc
  File "pandas/_libs/hashtable_class_helper.pxi", line 1614, in pandas._libs.hashtable.PyObjectHashTable.get_item
  File "pandas/_libs/hashtable_class_helper.pxi", line 1622, in pandas._libs.hashtable.PyObjectHashTable.get_item
KeyError: 'salesAmt'

During handling of the above exception, another exception occurred:

Traceback (most recent call last):
  File "/anaconda/envs/py37_default/lib/python3.7/site-packages/telegram/ext/dispatcher.py", line 447, in process_update
    handler.handle_update(update, self, check, context)
  File "/anaconda/envs/py37_default/lib/python3.7/site-packages/telegram/ext/handler.py", line 160, in handle_update
    return self.callback(update, context)
  File "/datadrive/Crontab/light_house_bot.py", line 939, in button
    df['cpm'] = int(round(df['salesAmt'] / df['impCnt'] * 1000))
  File "/anaconda/envs/py37_default/lib/python3.7/site-packages/pandas/core/frame.py", line 2800, in __getitem__
    indexer = self.columns.get_loc(key)
  File "/anaconda/envs/py37_default/lib/python3.7/site-packages/pandas/core/indexes/base.py", line 2648, in get_loc
    return self._engine.get_loc(self._maybe_cast_indexer(key))
  File "pandas/_libs/index.pyx", line 111, in pandas._libs.index.IndexEngine.get_loc
  File "pandas/_libs/index.pyx", line 138, in pandas._libs.index.IndexEngine.get_loc
  File "pandas/_libs/hashtable_class_helper.pxi", line 1614, in pandas._libs.hashtable.PyObjectHashTable.get_item
  File "pandas/_libs/hashtable_class_helper.pxi", line 1622, in pandas._libs.hashtable.PyObjectHashTable.get_item
KeyError: 'salesAmt'
No error handlers are registered, logging exception.
Traceback (most recent call last):
  File "/anaconda/envs/py37_default/lib/python3.7/site-packages/pandas/core/indexes/base.py", line 2646, in get_loc
    return self._engine.get_loc(key)
  File "pandas/_libs/index.pyx", line 111, in pandas._libs.index.IndexEngine.get_loc
  File "pandas/_libs/index.pyx", line 138, in pandas._libs.index.IndexEngine.get_loc
  File "pandas/_libs/hashtable_class_helper.pxi", line 1614, in pandas._libs.hashtable.PyObjectHashTable.get_item
  File "pandas/_libs/hashtable_class_helper.pxi", line 1622, in pandas._libs.hashtable.PyObjectHashTable.get_item
KeyError: 'salesAmt'

During handling of the above exception, another exception occurred:

Traceback (most recent call last):
  File "/anaconda/envs/py37_default/lib/python3.7/site-packages/telegram/ext/dispatcher.py", line 447, in process_update
    handler.handle_update(update, self, check, context)
  File "/anaconda/envs/py37_default/lib/python3.7/site-packages/telegram/ext/handler.py", line 160, in handle_update
    return self.callback(update, context)
  File "/datadrive/Crontab/light_house_bot.py", line 939, in button
    df['cpm'] = int(round(df['salesAmt'] / df['impCnt'] * 1000))
  File "/anaconda/envs/py37_default/lib/python3.7/site-packages/pandas/core/frame.py", line 2800, in __getitem__
    indexer = self.columns.get_loc(key)
  File "/anaconda/envs/py37_default/lib/python3.7/site-packages/pandas/core/indexes/base.py", line 2648, in get_loc
    return self._engine.get_loc(self._maybe_cast_indexer(key))
  File "pandas/_libs/index.pyx", line 111, in pandas._libs.index.IndexEngine.get_loc
  File "pandas/_libs/index.pyx", line 138, in pandas._libs.index.IndexEngine.get_loc
  File "pandas/_libs/hashtable_class_helper.pxi", line 1614, in pandas._libs.hashtable.PyObjectHashTable.get_item
  File "pandas/_libs/hashtable_class_helper.pxi", line 1622, in pandas._libs.hashtable.PyObjectHashTable.get_item
KeyError: 'salesAmt'
Killed
/datadrive/Crontab/light_house_bot.py:1639: TelegramDeprecationWarning: The argument `clean` of `start_polling` is deprecated. Please use `drop_pending_updates` instead.
  updater.start_polling(timeout=3, clean=True) #drop_pending_updates
[INFO] 2021-05-26 10:06:01,178 > 사용자 id :1459643056  닉 : ㅇ 
[INFO] 2021-05-26 15:52:37,897 > 사용자 id :1861198809  닉 : KIM 
Error while getting Updates: urllib3 HTTPError ('Connection aborted.', RemoteDisconnected('Remote end closed connection without response'))
No error handlers are registered, logging exception.
Traceback (most recent call last):
  File "/anaconda/envs/py37_default/lib/python3.7/site-packages/telegram/vendor/ptb_urllib3/urllib3/connectionpool.py", line 617, in urlopen
    chunked=chunked)
  File "/anaconda/envs/py37_default/lib/python3.7/site-packages/telegram/vendor/ptb_urllib3/urllib3/connectionpool.py", line 402, in _make_request
    six.raise_from(e, None)
  File "<string>", line 2, in raise_from
  File "/anaconda/envs/py37_default/lib/python3.7/site-packages/telegram/vendor/ptb_urllib3/urllib3/connectionpool.py", line 398, in _make_request
    httplib_response = conn.getresponse()
  File "/anaconda/envs/py37_default/lib/python3.7/http/client.py", line 1369, in getresponse
    response.begin()
  File "/anaconda/envs/py37_default/lib/python3.7/http/client.py", line 310, in begin
    version, status, reason = self._read_status()
  File "/anaconda/envs/py37_default/lib/python3.7/http/client.py", line 279, in _read_status
    raise RemoteDisconnected("Remote end closed connection without"
http.client.RemoteDisconnected: Remote end closed connection without response

During handling of the above exception, another exception occurred:

Traceback (most recent call last):
  File "/anaconda/envs/py37_default/lib/python3.7/site-packages/telegram/utils/request.py", line 253, in _request_wrapper
    resp = self._con_pool.request(*args, **kwargs)
  File "/anaconda/envs/py37_default/lib/python3.7/site-packages/telegram/vendor/ptb_urllib3/urllib3/request.py", line 70, in request
    **urlopen_kw)
  File "/anaconda/envs/py37_default/lib/python3.7/site-packages/telegram/vendor/ptb_urllib3/urllib3/request.py", line 148, in request_encode_body
    return self.urlopen(method, url, **extra_kw)
  File "/anaconda/envs/py37_default/lib/python3.7/site-packages/telegram/vendor/ptb_urllib3/urllib3/poolmanager.py", line 244, in urlopen
    response = conn.urlopen(method, u.request_uri, **kw)
  File "/anaconda/envs/py37_default/lib/python3.7/site-packages/telegram/vendor/ptb_urllib3/urllib3/connectionpool.py", line 666, in urlopen
    _stacktrace=sys.exc_info()[2])
  File "/anaconda/envs/py37_default/lib/python3.7/site-packages/telegram/vendor/ptb_urllib3/urllib3/util/retry.py", line 347, in increment
    raise six.reraise(type(error), error, _stacktrace)
  File "/anaconda/envs/py37_default/lib/python3.7/site-packages/telegram/vendor/ptb_urllib3/urllib3/packages/six.py", line 685, in reraise
    raise value.with_traceback(tb)
  File "/anaconda/envs/py37_default/lib/python3.7/site-packages/telegram/vendor/ptb_urllib3/urllib3/connectionpool.py", line 617, in urlopen
    chunked=chunked)
  File "/anaconda/envs/py37_default/lib/python3.7/site-packages/telegram/vendor/ptb_urllib3/urllib3/connectionpool.py", line 402, in _make_request
    six.raise_from(e, None)
  File "<string>", line 2, in raise_from
  File "/anaconda/envs/py37_default/lib/python3.7/site-packages/telegram/vendor/ptb_urllib3/urllib3/connectionpool.py", line 398, in _make_request
    httplib_response = conn.getresponse()
  File "/anaconda/envs/py37_default/lib/python3.7/http/client.py", line 1369, in getresponse
    response.begin()
  File "/anaconda/envs/py37_default/lib/python3.7/http/client.py", line 310, in begin
    version, status, reason = self._read_status()
  File "/anaconda/envs/py37_default/lib/python3.7/http/client.py", line 279, in _read_status
    raise RemoteDisconnected("Remote end closed connection without"
telegram.vendor.ptb_urllib3.urllib3.exceptions.ProtocolError: ('Connection aborted.', RemoteDisconnected('Remote end closed connection without response'))

The above exception was the direct cause of the following exception:

Traceback (most recent call last):
  File "/anaconda/envs/py37_default/lib/python3.7/site-packages/telegram/ext/updater.py", line 520, in _network_loop_retry
    if not action_cb():
  File "/anaconda/envs/py37_default/lib/python3.7/site-packages/telegram/ext/updater.py", line 475, in polling_action_cb
    allowed_updates=allowed_updates,
  File "/anaconda/envs/py37_default/lib/python3.7/site-packages/telegram/bot.py", line 127, in decorator
    result = func(*args, **kwargs)
  File "/anaconda/envs/py37_default/lib/python3.7/site-packages/telegram/bot.py", line 2762, in get_updates
    'getUpdates', data, timeout=float(read_latency) + float(timeout), api_kwargs=api_kwargs
  File "/anaconda/envs/py37_default/lib/python3.7/site-packages/telegram/bot.py", line 260, in _post
    f'{self.base_url}/{endpoint}', data=data, timeout=effective_timeout
  File "/anaconda/envs/py37_default/lib/python3.7/site-packages/telegram/utils/request.py", line 355, in post
    **urlopen_kwargs,
  File "/anaconda/envs/py37_default/lib/python3.7/site-packages/telegram/utils/request.py", line 259, in _request_wrapper
    raise NetworkError(f'urllib3 HTTPError {error}') from error
telegram.error.NetworkError: urllib3 HTTPError ('Connection aborted.', RemoteDisconnected('Remote end closed connection without response'))
[INFO] 2021-05-26 21:31:17,856 > 사용자 id :1861198809  닉 : KIM 
[INFO] 2021-05-26 21:32:23,437 > 사용자 id :1861198809  닉 : KIM 
[INFO] 2021-05-26 21:40:06,912 > 사용자 id :1861198809  닉 : KIM 
[INFO] 2021-05-26 21:44:55,613 > 사용자 id :1861198809  닉 : KIM 
[INFO] 2021-05-27 13:59:22,250 > 사용자 id :1459643056  닉 : ㅇ 
Error while getting Updates: Bad Gateway
No error handlers are registered, logging exception.
Traceback (most recent call last):
  File "/anaconda/envs/py37_default/lib/python3.7/site-packages/telegram/ext/updater.py", line 520, in _network_loop_retry
    if not action_cb():
  File "/anaconda/envs/py37_default/lib/python3.7/site-packages/telegram/ext/updater.py", line 475, in polling_action_cb
    allowed_updates=allowed_updates,
  File "/anaconda/envs/py37_default/lib/python3.7/site-packages/telegram/bot.py", line 127, in decorator
    result = func(*args, **kwargs)
  File "/anaconda/envs/py37_default/lib/python3.7/site-packages/telegram/bot.py", line 2762, in get_updates
    'getUpdates', data, timeout=float(read_latency) + float(timeout), api_kwargs=api_kwargs
  File "/anaconda/envs/py37_default/lib/python3.7/site-packages/telegram/bot.py", line 260, in _post
    f'{self.base_url}/{endpoint}', data=data, timeout=effective_timeout
  File "/anaconda/envs/py37_default/lib/python3.7/site-packages/telegram/utils/request.py", line 355, in post
    **urlopen_kwargs,
  File "/anaconda/envs/py37_default/lib/python3.7/site-packages/telegram/utils/request.py", line 284, in _request_wrapper
    raise NetworkError('Bad Gateway')
telegram.error.NetworkError: Bad Gateway
[INFO] 2021-05-28 14:34:50,820 > 사용자 id :1842443672  닉 : 정원 
No error handlers are registered, logging exception.
Traceback (most recent call last):
  File "/anaconda/envs/py37_default/lib/python3.7/site-packages/pandas/core/indexes/base.py", line 2646, in get_loc
    return self._engine.get_loc(key)
  File "pandas/_libs/index.pyx", line 111, in pandas._libs.index.IndexEngine.get_loc
  File "pandas/_libs/index.pyx", line 138, in pandas._libs.index.IndexEngine.get_loc
  File "pandas/_libs/hashtable_class_helper.pxi", line 1614, in pandas._libs.hashtable.PyObjectHashTable.get_item
  File "pandas/_libs/hashtable_class_helper.pxi", line 1622, in pandas._libs.hashtable.PyObjectHashTable.get_item
KeyError: 'salesAmt'

During handling of the above exception, another exception occurred:

Traceback (most recent call last):
  File "/anaconda/envs/py37_default/lib/python3.7/site-packages/telegram/ext/dispatcher.py", line 447, in process_update
    handler.handle_update(update, self, check, context)
  File "/anaconda/envs/py37_default/lib/python3.7/site-packages/telegram/ext/handler.py", line 160, in handle_update
    return self.callback(update, context)
  File "/datadrive/Crontab/light_house_bot.py", line 1156, in button
    df['cpm'] = int(round(df['salesAmt'] / df['impCnt'] * 1000))
  File "/anaconda/envs/py37_default/lib/python3.7/site-packages/pandas/core/frame.py", line 2800, in __getitem__
    indexer = self.columns.get_loc(key)
  File "/anaconda/envs/py37_default/lib/python3.7/site-packages/pandas/core/indexes/base.py", line 2648, in get_loc
    return self._engine.get_loc(self._maybe_cast_indexer(key))
  File "pandas/_libs/index.pyx", line 111, in pandas._libs.index.IndexEngine.get_loc
  File "pandas/_libs/index.pyx", line 138, in pandas._libs.index.IndexEngine.get_loc
  File "pandas/_libs/hashtable_class_helper.pxi", line 1614, in pandas._libs.hashtable.PyObjectHashTable.get_item
  File "pandas/_libs/hashtable_class_helper.pxi", line 1622, in pandas._libs.hashtable.PyObjectHashTable.get_item
KeyError: 'salesAmt'
Killed
/datadrive/Crontab/light_house_bot.py:1639: TelegramDeprecationWarning: The argument `clean` of `start_polling` is deprecated. Please use `drop_pending_updates` instead.
  updater.start_polling(timeout=3, clean=True) #drop_pending_updates
[INFO] 2021-06-07 10:28:51,414 > 사용자 id :1459643056  닉 : ㅇ 
No error handlers are registered, logging exception.
Traceback (most recent call last):
  File "/anaconda/envs/py37_default/lib/python3.7/site-packages/telegram/ext/dispatcher.py", line 447, in process_update
    handler.handle_update(update, self, check, context)
  File "/anaconda/envs/py37_default/lib/python3.7/site-packages/telegram/ext/handler.py", line 160, in handle_update
    return self.callback(update, context)
  File "/datadrive/Crontab/light_house_bot.py", line 1024, in button
    cmp_name = grp_list[0]['name']
IndexError: list index out of range
No error handlers are registered, logging exception.
Traceback (most recent call last):
  File "/anaconda/envs/py37_default/lib/python3.7/site-packages/pandas/core/indexes/base.py", line 2646, in get_loc
    return self._engine.get_loc(key)
  File "pandas/_libs/index.pyx", line 111, in pandas._libs.index.IndexEngine.get_loc
  File "pandas/_libs/index.pyx", line 138, in pandas._libs.index.IndexEngine.get_loc
  File "pandas/_libs/hashtable_class_helper.pxi", line 1614, in pandas._libs.hashtable.PyObjectHashTable.get_item
  File "pandas/_libs/hashtable_class_helper.pxi", line 1622, in pandas._libs.hashtable.PyObjectHashTable.get_item
KeyError: 'salesAmt'

During handling of the above exception, another exception occurred:

Traceback (most recent call last):
  File "/anaconda/envs/py37_default/lib/python3.7/site-packages/telegram/ext/dispatcher.py", line 447, in process_update
    handler.handle_update(update, self, check, context)
  File "/anaconda/envs/py37_default/lib/python3.7/site-packages/telegram/ext/handler.py", line 160, in handle_update
    return self.callback(update, context)
  File "/datadrive/Crontab/light_house_bot.py", line 1185, in button
    df['cpm'] = int(round(df['salesAmt'] / df['impCnt'] * 1000))
  File "/anaconda/envs/py37_default/lib/python3.7/site-packages/pandas/core/frame.py", line 2800, in __getitem__
    indexer = self.columns.get_loc(key)
  File "/anaconda/envs/py37_default/lib/python3.7/site-packages/pandas/core/indexes/base.py", line 2648, in get_loc
    return self._engine.get_loc(self._maybe_cast_indexer(key))
  File "pandas/_libs/index.pyx", line 111, in pandas._libs.index.IndexEngine.get_loc
  File "pandas/_libs/index.pyx", line 138, in pandas._libs.index.IndexEngine.get_loc
  File "pandas/_libs/hashtable_class_helper.pxi", line 1614, in pandas._libs.hashtable.PyObjectHashTable.get_item
  File "pandas/_libs/hashtable_class_helper.pxi", line 1622, in pandas._libs.hashtable.PyObjectHashTable.get_item
KeyError: 'salesAmt'
No error handlers are registered, logging exception.
Traceback (most recent call last):
  File "/anaconda/envs/py37_default/lib/python3.7/site-packages/pandas/core/indexes/base.py", line 2646, in get_loc
    return self._engine.get_loc(key)
  File "pandas/_libs/index.pyx", line 111, in pandas._libs.index.IndexEngine.get_loc
  File "pandas/_libs/index.pyx", line 138, in pandas._libs.index.IndexEngine.get_loc
  File "pandas/_libs/hashtable_class_helper.pxi", line 1614, in pandas._libs.hashtable.PyObjectHashTable.get_item
  File "pandas/_libs/hashtable_class_helper.pxi", line 1622, in pandas._libs.hashtable.PyObjectHashTable.get_item
KeyError: 'salesAmt'

During handling of the above exception, another exception occurred:

Traceback (most recent call last):
  File "/anaconda/envs/py37_default/lib/python3.7/site-packages/telegram/ext/dispatcher.py", line 447, in process_update
    handler.handle_update(update, self, check, context)
  File "/anaconda/envs/py37_default/lib/python3.7/site-packages/telegram/ext/handler.py", line 160, in handle_update
    return self.callback(update, context)
  File "/datadrive/Crontab/light_house_bot.py", line 1185, in button
    df['cpm'] = int(round(df['salesAmt'] / df['impCnt'] * 1000))
  File "/anaconda/envs/py37_default/lib/python3.7/site-packages/pandas/core/frame.py", line 2800, in __getitem__
    indexer = self.columns.get_loc(key)
  File "/anaconda/envs/py37_default/lib/python3.7/site-packages/pandas/core/indexes/base.py", line 2648, in get_loc
    return self._engine.get_loc(self._maybe_cast_indexer(key))
  File "pandas/_libs/index.pyx", line 111, in pandas._libs.index.IndexEngine.get_loc
  File "pandas/_libs/index.pyx", line 138, in pandas._libs.index.IndexEngine.get_loc
  File "pandas/_libs/hashtable_class_helper.pxi", line 1614, in pandas._libs.hashtable.PyObjectHashTable.get_item
  File "pandas/_libs/hashtable_class_helper.pxi", line 1622, in pandas._libs.hashtable.PyObjectHashTable.get_item
KeyError: 'salesAmt'
Killed
